[2022-06-25 17:08:09,673] {taskinstance.py:851} INFO - Dependencies all met for <TaskInstance: SDG_Enrique_V0.postgreSQL_getTable 2022-06-25T17:08:07.272551+00:00 [queued]>
[2022-06-25 17:08:09,688] {taskinstance.py:851} INFO - Dependencies all met for <TaskInstance: SDG_Enrique_V0.postgreSQL_getTable 2022-06-25T17:08:07.272551+00:00 [queued]>
[2022-06-25 17:08:09,688] {taskinstance.py:1042} INFO - 
--------------------------------------------------------------------------------
[2022-06-25 17:08:09,689] {taskinstance.py:1043} INFO - Starting attempt 1 of 1
[2022-06-25 17:08:09,689] {taskinstance.py:1044} INFO - 
--------------------------------------------------------------------------------
[2022-06-25 17:08:09,697] {taskinstance.py:1063} INFO - Executing <Task(PythonOperator): postgreSQL_getTable> on 2022-06-25T17:08:07.272551+00:00
[2022-06-25 17:08:09,703] {standard_task_runner.py:52} INFO - Started process 2150 to run task
[2022-06-25 17:08:09,706] {standard_task_runner.py:76} INFO - Running: ['airflow', 'tasks', 'run', 'SDG_Enrique_V0', 'postgreSQL_getTable', '2022-06-25T17:08:07.272551+00:00', '--job-id', '20', '--pool', 'default_pool', '--raw', '--subdir', 'DAGS_FOLDER/company_forecasting.py', '--cfg-path', '/tmp/tmp8gzwv22n', '--error-file', '/tmp/tmpe6fbo7d4']
[2022-06-25 17:08:09,710] {standard_task_runner.py:77} INFO - Job 20: Subtask postgreSQL_getTable
[2022-06-25 17:08:09,752] {logging_mixin.py:104} INFO - Running <TaskInstance: SDG_Enrique_V0.postgreSQL_getTable 2022-06-25T17:08:07.272551+00:00 [running]> on host 7ba8bbebd0a2
[2022-06-25 17:08:09,796] {taskinstance.py:1257} INFO - Exporting the following env vars:
AIRFLOW_CTX_DAG_EMAIL=enrique-liebana@outlook.com
AIRFLOW_CTX_DAG_OWNER=Enrique
AIRFLOW_CTX_DAG_ID=SDG_Enrique_V0
AIRFLOW_CTX_TASK_ID=postgreSQL_getTable
AIRFLOW_CTX_EXECUTION_DATE=2022-06-25T17:08:07.272551+00:00
AIRFLOW_CTX_DAG_RUN_ID=manual__2022-06-25T17:08:07.272551+00:00
[2022-06-25 17:08:09,808] {base.py:74} INFO - Using connection to: id: postgres_conection. Host: host.docker.internal, Port: 5432, Schema: data_company, Login: airflow, Password: XXXXXXXX, extra: None
[2022-06-25 17:08:09,824] {taskinstance.py:1455} ERROR - FATAL:  database "data_company" does not exist
Traceback (most recent call last):
  File "/home/airflow/.local/lib/python3.6/site-packages/airflow/models/taskinstance.py", line 1112, in _run_raw_task
    self._prepare_and_execute_task_with_callbacks(context, task)
  File "/home/airflow/.local/lib/python3.6/site-packages/airflow/models/taskinstance.py", line 1285, in _prepare_and_execute_task_with_callbacks
    result = self._execute_task(context, task_copy)
  File "/home/airflow/.local/lib/python3.6/site-packages/airflow/models/taskinstance.py", line 1315, in _execute_task
    result = task_copy.execute(context=context)
  File "/home/airflow/.local/lib/python3.6/site-packages/airflow/operators/python.py", line 117, in execute
    return_value = self.execute_callable()
  File "/home/airflow/.local/lib/python3.6/site-packages/airflow/operators/python.py", line 128, in execute_callable
    return self.python_callable(*self.op_args, **self.op_kwargs)
  File "/opt/airflow/dags/company_forecasting.py", line 45, in postgreSQL_getTable
    conn = hook.get_conn()
  File "/home/airflow/.local/lib/python3.6/site-packages/airflow/providers/postgres/hooks/postgres.py", line 108, in get_conn
    self.conn = psycopg2.connect(**conn_args)
  File "/home/airflow/.local/lib/python3.6/site-packages/psycopg2/__init__.py", line 127, in connect
    conn = _connect(dsn, connection_factory=connection_factory, **kwasync)
psycopg2.OperationalError: FATAL:  database "data_company" does not exist

[2022-06-25 17:08:09,831] {taskinstance.py:1503} INFO - Marking task as FAILED. dag_id=SDG_Enrique_V0, task_id=postgreSQL_getTable, execution_date=20220625T170807, start_date=20220625T170809, end_date=20220625T170809
[2022-06-25 17:08:09,882] {local_task_job.py:146} INFO - Task exited with return code 1
