[2022-06-26 20:37:59,688] {taskinstance.py:851} INFO - Dependencies all met for <TaskInstance: trigger_dag.gridSearchLR 2022-06-26T20:37:57.580661+00:00 [queued]>
[2022-06-26 20:37:59,712] {taskinstance.py:851} INFO - Dependencies all met for <TaskInstance: trigger_dag.gridSearchLR 2022-06-26T20:37:57.580661+00:00 [queued]>
[2022-06-26 20:37:59,713] {taskinstance.py:1042} INFO - 
--------------------------------------------------------------------------------
[2022-06-26 20:37:59,714] {taskinstance.py:1043} INFO - Starting attempt 1 of 1
[2022-06-26 20:37:59,715] {taskinstance.py:1044} INFO - 
--------------------------------------------------------------------------------
[2022-06-26 20:37:59,726] {taskinstance.py:1063} INFO - Executing <Task(PythonOperator): gridSearchLR> on 2022-06-26T20:37:57.580661+00:00
[2022-06-26 20:37:59,736] {standard_task_runner.py:52} INFO - Started process 6891 to run task
[2022-06-26 20:37:59,741] {standard_task_runner.py:76} INFO - Running: ['airflow', 'tasks', 'run', 'trigger_dag', 'gridSearchLR', '2022-06-26T20:37:57.580661+00:00', '--job-id', '308', '--pool', 'default_pool', '--raw', '--subdir', 'DAGS_FOLDER/trigger_dag.py', '--cfg-path', '/tmp/tmp8fgwh3x3', '--error-file', '/tmp/tmppv05b2pu']
[2022-06-26 20:37:59,745] {standard_task_runner.py:77} INFO - Job 308: Subtask gridSearchLR
[2022-06-26 20:37:59,796] {logging_mixin.py:104} INFO - Running <TaskInstance: trigger_dag.gridSearchLR 2022-06-26T20:37:57.580661+00:00 [running]> on host 6fc8504e86cf
[2022-06-26 20:37:59,841] {taskinstance.py:1257} INFO - Exporting the following env vars:
AIRFLOW_CTX_DAG_OWNER=airflow
AIRFLOW_CTX_DAG_ID=trigger_dag
AIRFLOW_CTX_TASK_ID=gridSearchLR
AIRFLOW_CTX_EXECUTION_DATE=2022-06-26T20:37:57.580661+00:00
AIRFLOW_CTX_DAG_RUN_ID=manual__2022-06-26T20:37:57.580661+00:00
[2022-06-26 20:37:59,844] {taskinstance.py:1455} ERROR - [Errno 13] Permission denied: '/Users'
Traceback (most recent call last):
  File "/home/airflow/.local/lib/python3.6/site-packages/airflow/models/taskinstance.py", line 1112, in _run_raw_task
    self._prepare_and_execute_task_with_callbacks(context, task)
  File "/home/airflow/.local/lib/python3.6/site-packages/airflow/models/taskinstance.py", line 1285, in _prepare_and_execute_task_with_callbacks
    result = self._execute_task(context, task_copy)
  File "/home/airflow/.local/lib/python3.6/site-packages/airflow/models/taskinstance.py", line 1315, in _execute_task
    result = task_copy.execute(context=context)
  File "/home/airflow/.local/lib/python3.6/site-packages/airflow/operators/python.py", line 117, in execute
    return_value = self.execute_callable()
  File "/home/airflow/.local/lib/python3.6/site-packages/airflow/operators/python.py", line 128, in execute_callable
    return self.python_callable(*self.op_args, **self.op_kwargs)
  File "/opt/airflow/dags/trigger_dag.py", line 28, in check_mlflow_setting
    client = MlflowClient()
  File "/home/airflow/.local/lib/python3.6/site-packages/mlflow/tracking/client.py", line 70, in __init__
    self._tracking_client = TrackingServiceClient(final_tracking_uri)
  File "/home/airflow/.local/lib/python3.6/site-packages/mlflow/tracking/_tracking_service/client.py", line 48, in __init__
    self.store
  File "/home/airflow/.local/lib/python3.6/site-packages/mlflow/tracking/_tracking_service/client.py", line 52, in store
    return utils._get_store(self.tracking_uri)
  File "/home/airflow/.local/lib/python3.6/site-packages/mlflow/tracking/_tracking_service/utils.py", line 155, in _get_store
    return _tracking_store_registry.get_store(store_uri, artifact_uri)
  File "/home/airflow/.local/lib/python3.6/site-packages/mlflow/tracking/_tracking_service/registry.py", line 39, in get_store
    return self._get_store_with_resolved_uri(resolved_store_uri, artifact_uri)
  File "/home/airflow/.local/lib/python3.6/site-packages/mlflow/tracking/_tracking_service/registry.py", line 49, in _get_store_with_resolved_uri
    return builder(store_uri=resolved_store_uri, artifact_uri=artifact_uri)
  File "/home/airflow/.local/lib/python3.6/site-packages/mlflow/tracking/_tracking_service/utils.py", line 109, in _get_file_store
    return FileStore(store_uri, store_uri)
  File "/home/airflow/.local/lib/python3.6/site-packages/mlflow/store/tracking/file_store.py", line 140, in __init__
    mkdir(self.root_directory)
  File "/home/airflow/.local/lib/python3.6/site-packages/mlflow/utils/file_utils.py", line 114, in mkdir
    raise e
  File "/home/airflow/.local/lib/python3.6/site-packages/mlflow/utils/file_utils.py", line 111, in mkdir
    os.makedirs(target)
  File "/usr/local/lib/python3.6/os.py", line 210, in makedirs
    makedirs(head, mode, exist_ok)
  File "/usr/local/lib/python3.6/os.py", line 210, in makedirs
    makedirs(head, mode, exist_ok)
  File "/usr/local/lib/python3.6/os.py", line 210, in makedirs
    makedirs(head, mode, exist_ok)
  File "/usr/local/lib/python3.6/os.py", line 220, in makedirs
    mkdir(name, mode)
PermissionError: [Errno 13] Permission denied: '/Users'
[2022-06-26 20:37:59,854] {taskinstance.py:1503} INFO - Marking task as FAILED. dag_id=trigger_dag, task_id=gridSearchLR, execution_date=20220626T203757, start_date=20220626T203759, end_date=20220626T203759
[2022-06-26 20:37:59,918] {local_task_job.py:146} INFO - Task exited with return code 1
