[2022-06-25 20:49:39,943] {taskinstance.py:851} INFO - Dependencies all met for <TaskInstance: SDG_Enrique_V0.readCSV_convertColumns 2022-06-25T20:49:24.600748+00:00 [queued]>
[2022-06-25 20:49:39,960] {taskinstance.py:851} INFO - Dependencies all met for <TaskInstance: SDG_Enrique_V0.readCSV_convertColumns 2022-06-25T20:49:24.600748+00:00 [queued]>
[2022-06-25 20:49:39,961] {taskinstance.py:1042} INFO - 
--------------------------------------------------------------------------------
[2022-06-25 20:49:39,962] {taskinstance.py:1043} INFO - Starting attempt 1 of 1
[2022-06-25 20:49:39,962] {taskinstance.py:1044} INFO - 
--------------------------------------------------------------------------------
[2022-06-25 20:49:39,970] {taskinstance.py:1063} INFO - Executing <Task(PythonOperator): readCSV_convertColumns> on 2022-06-25T20:49:24.600748+00:00
[2022-06-25 20:49:39,977] {standard_task_runner.py:52} INFO - Started process 4030 to run task
[2022-06-25 20:49:39,981] {standard_task_runner.py:76} INFO - Running: ['airflow', 'tasks', 'run', 'SDG_Enrique_V0', 'readCSV_convertColumns', '2022-06-25T20:49:24.600748+00:00', '--job-id', '142', '--pool', 'default_pool', '--raw', '--subdir', 'DAGS_FOLDER/company_forecasting.py', '--cfg-path', '/tmp/tmp7sq_tj92', '--error-file', '/tmp/tmpg611bim4']
[2022-06-25 20:49:39,983] {standard_task_runner.py:77} INFO - Job 142: Subtask readCSV_convertColumns
[2022-06-25 20:49:40,040] {logging_mixin.py:104} INFO - Running <TaskInstance: SDG_Enrique_V0.readCSV_convertColumns 2022-06-25T20:49:24.600748+00:00 [running]> on host 5e8dc4b25004
[2022-06-25 20:49:40,086] {taskinstance.py:1257} INFO - Exporting the following env vars:
AIRFLOW_CTX_DAG_EMAIL=enrique-liebana@outlook.com
AIRFLOW_CTX_DAG_OWNER=Enrique
AIRFLOW_CTX_DAG_ID=SDG_Enrique_V0
AIRFLOW_CTX_TASK_ID=readCSV_convertColumns
AIRFLOW_CTX_EXECUTION_DATE=2022-06-25T20:49:24.600748+00:00
AIRFLOW_CTX_DAG_RUN_ID=manual__2022-06-25T20:49:24.600748+00:00
[2022-06-25 20:49:43,295] {logging_mixin.py:104} WARNING - /home/airflow/.local/lib/python3.6/site-packages/airflow/models/taskinstance.py:1315 DtypeWarning: Columns (46,56,59) have mixed types.Specify dtype option on import or set low_memory=False.
[2022-06-25 20:49:43,659] {logging_mixin.py:104} INFO -   rev_mean mou_mean totmrc_mean  ... creditcd eqpdays customer_id
0  23,9975   219,25        22,5  ...        Y   361.0     1000001
1  57,4925   482,75      37,425  ...        Y   240.0     1000002
2    16,99    10,25       16,99  ...        Y  1504.0     1000003
3       38      7,5          38  ...        Y  1812.0     1000004
4    55,23    570,5       71,98  ...        Y   434.0     1000005

[5 rows x 100 columns]
[2022-06-25 20:49:43,663] {logging_mixin.py:104} INFO - rev_mean        object
mou_mean        object
totmrc_mean     object
da_mean         object
ovrmou_mean     object
                ...   
kid11_15        object
kid16_17        object
creditcd        object
eqpdays        float64
customer_id      int64
Length: 100, dtype: object
[2022-06-25 20:49:43,665] {logging_mixin.py:104} INFO - **************** FLOAT COLUmNS *********************
[2022-06-25 20:49:49,177] {logging_mixin.py:104} INFO - **************** OBJECT COLUmNS *********************
[2022-06-25 20:49:49,633] {logging_mixin.py:104} INFO - ************+***********RESULTS*****************************
[2022-06-25 20:49:49,649] {logging_mixin.py:104} INFO - FLOAT64 (100000, 68)
[2022-06-25 20:49:49,653] {logging_mixin.py:104} INFO - INT64 (100000, 11)
[2022-06-25 20:49:49,655] {logging_mixin.py:104} INFO - STRING (100000, 21)
[2022-06-25 20:49:58,155] {base.py:74} INFO - Using connection to: id: postgres_conection. Host: host.docker.internal, Port: 5432, Schema: data_company, Login: airflow, Password: XXXXXXXX, extra: None
[2022-06-25 20:49:59,350] {taskinstance.py:1455} ERROR - extra data after last expected column
CONTEXT:  COPY company_a01, line 2: "0,,,,,0.0,0.0,0.0,0.0,0.0,,,,0.0,,0.0,,0.0,,0.0,,0,45.0,0.0,0.0,0.0,0.0,18.0,0.0,,0.0,,0.0,0.0,0.0,0..."
Traceback (most recent call last):
  File "/home/airflow/.local/lib/python3.6/site-packages/airflow/models/taskinstance.py", line 1112, in _run_raw_task
    self._prepare_and_execute_task_with_callbacks(context, task)
  File "/home/airflow/.local/lib/python3.6/site-packages/airflow/models/taskinstance.py", line 1285, in _prepare_and_execute_task_with_callbacks
    result = self._execute_task(context, task_copy)
  File "/home/airflow/.local/lib/python3.6/site-packages/airflow/models/taskinstance.py", line 1315, in _execute_task
    result = task_copy.execute(context=context)
  File "/home/airflow/.local/lib/python3.6/site-packages/airflow/operators/python.py", line 117, in execute
    return_value = self.execute_callable()
  File "/home/airflow/.local/lib/python3.6/site-packages/airflow/operators/python.py", line 128, in execute_callable
    return self.python_callable(*self.op_args, **self.op_kwargs)
  File "/opt/airflow/dags/company_forecasting.py", line 214, in read_and_convertColumns
    cur.copy_expert(sql=sql % table, file=file)
psycopg2.errors.BadCopyFileFormat: extra data after last expected column
CONTEXT:  COPY company_a01, line 2: "0,,,,,0.0,0.0,0.0,0.0,0.0,,,,0.0,,0.0,,0.0,,0.0,,0,45.0,0.0,0.0,0.0,0.0,18.0,0.0,,0.0,,0.0,0.0,0.0,0..."

[2022-06-25 20:49:59,356] {taskinstance.py:1503} INFO - Marking task as FAILED. dag_id=SDG_Enrique_V0, task_id=readCSV_convertColumns, execution_date=20220625T204924, start_date=20220625T204939, end_date=20220625T204959
[2022-06-25 20:49:59,453] {local_task_job.py:146} INFO - Task exited with return code 1
