[2022-06-29 20:53:23,158] {taskinstance.py:851} INFO - Dependencies all met for <TaskInstance: Company_Predict.trigger_target 2022-01-10T00:00:00+00:00 [None]>
[2022-06-29 20:53:23,246] {taskinstance.py:851} INFO - Dependencies all met for <TaskInstance: Company_Predict.trigger_target 2022-01-10T00:00:00+00:00 [None]>
[2022-06-29 20:53:23,250] {taskinstance.py:1042} INFO - 
--------------------------------------------------------------------------------
[2022-06-29 20:53:23,256] {taskinstance.py:1043} INFO - Starting attempt 1 of 2
[2022-06-29 20:53:23,271] {taskinstance.py:1044} INFO - 
--------------------------------------------------------------------------------
[2022-06-29 20:53:23,520] {taskinstance.py:1063} INFO - Executing <Task(TriggerDagRunOperator): trigger_target> on 2022-01-10T00:00:00+00:00
[2022-06-29 20:53:23,595] {standard_task_runner.py:52} INFO - Started process 1257 to run task
[2022-06-29 20:53:23,651] {standard_task_runner.py:76} INFO - Running: ['airflow', 'tasks', 'run', 'Company_Predict', 'trigger_target', '2022-01-10T00:00:00+00:00', '--job-id', '1337', '--pool', 'default_pool', '--raw', '--subdir', 'DAGS_FOLDER/company_predict.py', '--cfg-path', '/tmp/tmpi45skrjl', '--error-file', '/tmp/tmp3jwe_snh']
[2022-06-29 20:53:23,664] {standard_task_runner.py:77} INFO - Job 1337: Subtask trigger_target
[2022-06-29 20:53:24,251] {logging_mixin.py:104} INFO - Running <TaskInstance: Company_Predict.trigger_target 2022-01-10T00:00:00+00:00 [running]> on host 1ff8f57a8cbf
[2022-06-29 20:53:24,726] {taskinstance.py:1257} INFO - Exporting the following env vars:
AIRFLOW_CTX_DAG_EMAIL=enrique-liebana@outlook.com
AIRFLOW_CTX_DAG_OWNER=Enrique Liebana Peña
AIRFLOW_CTX_DAG_ID=Company_Predict
AIRFLOW_CTX_TASK_ID=trigger_target
AIRFLOW_CTX_EXECUTION_DATE=2022-01-10T00:00:00+00:00
[2022-06-29 20:53:24,955] {taskinstance.py:1455} ERROR - Dag id SDG_Enrique_V0 not found in DagModel
Traceback (most recent call last):
  File "/home/airflow/.local/lib/python3.6/site-packages/airflow/models/taskinstance.py", line 1112, in _run_raw_task
    self._prepare_and_execute_task_with_callbacks(context, task)
  File "/home/airflow/.local/lib/python3.6/site-packages/airflow/models/taskinstance.py", line 1285, in _prepare_and_execute_task_with_callbacks
    result = self._execute_task(context, task_copy)
  File "/home/airflow/.local/lib/python3.6/site-packages/airflow/models/taskinstance.py", line 1315, in _execute_task
    result = task_copy.execute(context=context)
  File "/home/airflow/.local/lib/python3.6/site-packages/airflow/operators/trigger_dagrun.py", line 135, in execute
    replace_microseconds=False,
  File "/home/airflow/.local/lib/python3.6/site-packages/airflow/api/common/experimental/trigger_dag.py", line 114, in trigger_dag
    raise DagNotFound(f"Dag id {dag_id} not found in DagModel")
airflow.exceptions.DagNotFound: Dag id SDG_Enrique_V0 not found in DagModel
[2022-06-29 20:53:24,962] {taskinstance.py:1503} INFO - Marking task as UP_FOR_RETRY. dag_id=Company_Predict, task_id=trigger_target, execution_date=20220110T000000, start_date=20220629T205323, end_date=20220629T205324
[2022-06-29 20:53:25,297] {local_task_job.py:146} INFO - Task exited with return code 1
[2022-06-29 20:56:27,244] {taskinstance.py:851} INFO - Dependencies all met for <TaskInstance: Company_Predict.trigger_target 2022-01-10T00:00:00+00:00 [queued]>
[2022-06-29 20:56:27,384] {taskinstance.py:851} INFO - Dependencies all met for <TaskInstance: Company_Predict.trigger_target 2022-01-10T00:00:00+00:00 [queued]>
[2022-06-29 20:56:27,390] {taskinstance.py:1042} INFO - 
--------------------------------------------------------------------------------
[2022-06-29 20:56:27,397] {taskinstance.py:1043} INFO - Starting attempt 1 of 1
[2022-06-29 20:56:27,399] {taskinstance.py:1044} INFO - 
--------------------------------------------------------------------------------
[2022-06-29 20:56:27,508] {taskinstance.py:1063} INFO - Executing <Task(TriggerDagRunOperator): trigger_target> on 2022-01-10T00:00:00+00:00
[2022-06-29 20:56:27,572] {standard_task_runner.py:52} INFO - Started process 1636 to run task
[2022-06-29 20:56:27,636] {standard_task_runner.py:76} INFO - Running: ['airflow', 'tasks', 'run', 'Company_Predict', 'trigger_target', '2022-01-10T00:00:00+00:00', '--job-id', '1371', '--pool', 'default_pool', '--raw', '--subdir', 'DAGS_FOLDER/company_predict.py', '--cfg-path', '/tmp/tmp7uk0lbu9', '--error-file', '/tmp/tmpsb2zvxqp']
[2022-06-29 20:56:27,659] {standard_task_runner.py:77} INFO - Job 1371: Subtask trigger_target
[2022-06-29 20:56:27,993] {logging_mixin.py:104} INFO - Running <TaskInstance: Company_Predict.trigger_target 2022-01-10T00:00:00+00:00 [running]> on host 1ff8f57a8cbf
[2022-06-29 20:56:28,209] {taskinstance.py:1257} INFO - Exporting the following env vars:
AIRFLOW_CTX_DAG_EMAIL=enrique-liebana@outlook.com
AIRFLOW_CTX_DAG_OWNER=Enrique Liebana Peña
AIRFLOW_CTX_DAG_ID=Company_Predict
AIRFLOW_CTX_TASK_ID=trigger_target
AIRFLOW_CTX_EXECUTION_DATE=2022-01-10T00:00:00+00:00
AIRFLOW_CTX_DAG_RUN_ID=scheduled__2022-01-10T00:00:00+00:00
[2022-06-29 20:56:28,391] {trigger_dagrun.py:165} INFO - Waiting for SDG_Enrique_V0 on 2022-01-10T00:00:00+00:00 to become allowed state ['success'] ...
[2022-06-29 20:57:28,663] {taskinstance.py:1455} ERROR - No row was found for one()
Traceback (most recent call last):
  File "/home/airflow/.local/lib/python3.6/site-packages/airflow/models/taskinstance.py", line 1112, in _run_raw_task
    self._prepare_and_execute_task_with_callbacks(context, task)
  File "/home/airflow/.local/lib/python3.6/site-packages/airflow/models/taskinstance.py", line 1285, in _prepare_and_execute_task_with_callbacks
    result = self._execute_task(context, task_copy)
  File "/home/airflow/.local/lib/python3.6/site-packages/airflow/models/taskinstance.py", line 1315, in _execute_task
    result = task_copy.execute(context=context)
  File "/home/airflow/.local/lib/python3.6/site-packages/airflow/operators/trigger_dagrun.py", line 169, in execute
    dag_run.refresh_from_db()
  File "/home/airflow/.local/lib/python3.6/site-packages/airflow/utils/session.py", line 65, in wrapper
    return func(*args, session=session, **kwargs)
  File "/home/airflow/.local/lib/python3.6/site-packages/airflow/models/dagrun.py", line 178, in refresh_from_db
    DR.run_id == self.run_id,
  File "/home/airflow/.local/lib/python3.6/site-packages/sqlalchemy/orm/query.py", line 3500, in one
    raise orm_exc.NoResultFound("No row was found for one()")
sqlalchemy.orm.exc.NoResultFound: No row was found for one()
[2022-06-29 20:57:29,001] {taskinstance.py:1503} INFO - Marking task as FAILED. dag_id=Company_Predict, task_id=trigger_target, execution_date=20220110T000000, start_date=20220629T205627, end_date=20220629T205729
[2022-06-29 20:57:32,461] {local_task_job.py:146} INFO - Task exited with return code 1
