[2022-06-29 21:03:16,597] {taskinstance.py:851} INFO - Dependencies all met for <TaskInstance: Company_Predict.load_Model 2022-06-29T20:59:05.660689+00:00 [queued]>
[2022-06-29 21:03:16,614] {taskinstance.py:851} INFO - Dependencies all met for <TaskInstance: Company_Predict.load_Model 2022-06-29T20:59:05.660689+00:00 [queued]>
[2022-06-29 21:03:16,614] {taskinstance.py:1042} INFO - 
--------------------------------------------------------------------------------
[2022-06-29 21:03:16,615] {taskinstance.py:1043} INFO - Starting attempt 1 of 1
[2022-06-29 21:03:16,616] {taskinstance.py:1044} INFO - 
--------------------------------------------------------------------------------
[2022-06-29 21:03:16,625] {taskinstance.py:1063} INFO - Executing <Task(PythonOperator): load_Model> on 2022-06-29T20:59:05.660689+00:00
[2022-06-29 21:03:16,614] {standard_task_runner.py:52} INFO - Started process 641 to run task
[2022-06-29 21:03:16,618] {standard_task_runner.py:76} INFO - Running: ['airflow', 'tasks', 'run', 'Company_Predict', 'load_Model', '2022-06-29T20:59:05.660689+00:00', '--job-id', '1395', '--pool', 'default_pool', '--raw', '--subdir', 'DAGS_FOLDER/company_predict.py', '--cfg-path', '/tmp/tmpftzkvsvx', '--error-file', '/tmp/tmpglwxnx2g']
[2022-06-29 21:03:16,622] {standard_task_runner.py:77} INFO - Job 1395: Subtask load_Model
[2022-06-29 21:03:16,714] {logging_mixin.py:104} INFO - Running <TaskInstance: Company_Predict.load_Model 2022-06-29T20:59:05.660689+00:00 [running]> on host 1ff8f57a8cbf
[2022-06-29 21:03:16,799] {taskinstance.py:1257} INFO - Exporting the following env vars:
AIRFLOW_CTX_DAG_EMAIL=enrique-liebana@outlook.com
AIRFLOW_CTX_DAG_OWNER=Enrique Liebana Pe√±a
AIRFLOW_CTX_DAG_ID=Company_Predict
AIRFLOW_CTX_TASK_ID=load_Model
AIRFLOW_CTX_EXECUTION_DATE=2022-06-29T20:59:05.660689+00:00
AIRFLOW_CTX_DAG_RUN_ID=manual__2022-06-29T20:59:05.660689+00:00
[2022-06-29 21:03:24,631] {taskinstance.py:1455} ERROR - [Errno 2] No such file or directory: 'models/xgboost.pkl'
Traceback (most recent call last):
  File "/home/airflow/.local/lib/python3.6/site-packages/airflow/models/taskinstance.py", line 1112, in _run_raw_task
    self._prepare_and_execute_task_with_callbacks(context, task)
  File "/home/airflow/.local/lib/python3.6/site-packages/airflow/models/taskinstance.py", line 1285, in _prepare_and_execute_task_with_callbacks
    result = self._execute_task(context, task_copy)
  File "/home/airflow/.local/lib/python3.6/site-packages/airflow/models/taskinstance.py", line 1315, in _execute_task
    result = task_copy.execute(context=context)
  File "/home/airflow/.local/lib/python3.6/site-packages/airflow/operators/python.py", line 117, in execute
    return_value = self.execute_callable()
  File "/home/airflow/.local/lib/python3.6/site-packages/airflow/operators/python.py", line 128, in execute_callable
    return self.python_callable(*self.op_args, **self.op_kwargs)
  File "/opt/airflow/dags/company_predict.py", line 30, in _load_model
    pickled_model = pickle.load(open('models/xgboost.pkl', 'rb'))
FileNotFoundError: [Errno 2] No such file or directory: 'models/xgboost.pkl'
[2022-06-29 21:03:24,637] {taskinstance.py:1503} INFO - Marking task as FAILED. dag_id=Company_Predict, task_id=load_Model, execution_date=20220629T205905, start_date=20220629T210316, end_date=20220629T210324
[2022-06-29 21:03:24,714] {local_task_job.py:146} INFO - Task exited with return code 1
