[2022-06-25 19:31:31,830] {taskinstance.py:851} INFO - Dependencies all met for <TaskInstance: SDG_Enrique_V0.readCSV_convertColumns 2022-06-25T19:31:14.871669+00:00 [queued]>
[2022-06-25 19:31:31,846] {taskinstance.py:851} INFO - Dependencies all met for <TaskInstance: SDG_Enrique_V0.readCSV_convertColumns 2022-06-25T19:31:14.871669+00:00 [queued]>
[2022-06-25 19:31:31,846] {taskinstance.py:1042} INFO - 
--------------------------------------------------------------------------------
[2022-06-25 19:31:31,847] {taskinstance.py:1043} INFO - Starting attempt 1 of 1
[2022-06-25 19:31:31,848] {taskinstance.py:1044} INFO - 
--------------------------------------------------------------------------------
[2022-06-25 19:31:31,856] {taskinstance.py:1063} INFO - Executing <Task(PythonOperator): readCSV_convertColumns> on 2022-06-25T19:31:14.871669+00:00
[2022-06-25 19:31:31,864] {standard_task_runner.py:52} INFO - Started process 598 to run task
[2022-06-25 19:31:31,867] {standard_task_runner.py:76} INFO - Running: ['airflow', 'tasks', 'run', 'SDG_Enrique_V0', 'readCSV_convertColumns', '2022-06-25T19:31:14.871669+00:00', '--job-id', '120', '--pool', 'default_pool', '--raw', '--subdir', 'DAGS_FOLDER/company_forecasting.py', '--cfg-path', '/tmp/tmppnixysex', '--error-file', '/tmp/tmp684b2llx']
[2022-06-25 19:31:31,870] {standard_task_runner.py:77} INFO - Job 120: Subtask readCSV_convertColumns
[2022-06-25 19:31:31,913] {logging_mixin.py:104} INFO - Running <TaskInstance: SDG_Enrique_V0.readCSV_convertColumns 2022-06-25T19:31:14.871669+00:00 [running]> on host 5e8dc4b25004
[2022-06-25 19:31:31,951] {taskinstance.py:1257} INFO - Exporting the following env vars:
AIRFLOW_CTX_DAG_EMAIL=enrique-liebana@outlook.com
AIRFLOW_CTX_DAG_OWNER=Enrique
AIRFLOW_CTX_DAG_ID=SDG_Enrique_V0
AIRFLOW_CTX_TASK_ID=readCSV_convertColumns
AIRFLOW_CTX_EXECUTION_DATE=2022-06-25T19:31:14.871669+00:00
AIRFLOW_CTX_DAG_RUN_ID=manual__2022-06-25T19:31:14.871669+00:00
[2022-06-25 19:31:34,364] {logging_mixin.py:104} WARNING - /home/airflow/.local/lib/python3.6/site-packages/airflow/models/taskinstance.py:1315 DtypeWarning: Columns (46,56,59) have mixed types.Specify dtype option on import or set low_memory=False.
[2022-06-25 19:31:34,751] {logging_mixin.py:104} INFO -   rev_mean mou_mean totmrc_mean  ... creditcd eqpdays customer_id
0  23,9975   219,25        22,5  ...        Y   361.0     1000001
1  57,4925   482,75      37,425  ...        Y   240.0     1000002
2    16,99    10,25       16,99  ...        Y  1504.0     1000003
3       38      7,5          38  ...        Y  1812.0     1000004
4    55,23    570,5       71,98  ...        Y   434.0     1000005

[5 rows x 100 columns]
[2022-06-25 19:31:34,754] {logging_mixin.py:104} INFO - rev_mean        object
mou_mean        object
totmrc_mean     object
da_mean         object
ovrmou_mean     object
                ...   
kid11_15        object
kid16_17        object
creditcd        object
eqpdays        float64
customer_id      int64
Length: 100, dtype: object
[2022-06-25 19:31:34,755] {logging_mixin.py:104} INFO - **************** FLOAT COLUmNS *********************
[2022-06-25 19:31:40,465] {logging_mixin.py:104} INFO - **************** OBJECT COLUmNS *********************
[2022-06-25 19:31:40,937] {logging_mixin.py:104} INFO - ************+***********RESULTS*****************************
[2022-06-25 19:31:40,954] {logging_mixin.py:104} INFO - FLOAT64 (100000, 68)
[2022-06-25 19:31:40,958] {logging_mixin.py:104} INFO - INT64 (100000, 11)
[2022-06-25 19:31:40,960] {logging_mixin.py:104} INFO - STRING (100000, 21)
[2022-06-25 19:31:49,727] {taskinstance.py:1455} ERROR - (psycopg2.OperationalError) could not connect to server: Connection refused
	Is the server running on host "127.0.0.1" and accepting
	TCP/IP connections on port 5432?

(Background on this error at: http://sqlalche.me/e/13/e3q8)
Traceback (most recent call last):
  File "/home/airflow/.local/lib/python3.6/site-packages/sqlalchemy/engine/base.py", line 2336, in _wrap_pool_connect
    return fn()
  File "/home/airflow/.local/lib/python3.6/site-packages/sqlalchemy/pool/base.py", line 364, in connect
    return _ConnectionFairy._checkout(self)
  File "/home/airflow/.local/lib/python3.6/site-packages/sqlalchemy/pool/base.py", line 778, in _checkout
    fairy = _ConnectionRecord.checkout(pool)
  File "/home/airflow/.local/lib/python3.6/site-packages/sqlalchemy/pool/base.py", line 495, in checkout
    rec = pool._do_get()
  File "/home/airflow/.local/lib/python3.6/site-packages/sqlalchemy/pool/impl.py", line 140, in _do_get
    self._dec_overflow()
  File "/home/airflow/.local/lib/python3.6/site-packages/sqlalchemy/util/langhelpers.py", line 70, in __exit__
    with_traceback=exc_tb,
  File "/home/airflow/.local/lib/python3.6/site-packages/sqlalchemy/util/compat.py", line 182, in raise_
    raise exception
  File "/home/airflow/.local/lib/python3.6/site-packages/sqlalchemy/pool/impl.py", line 137, in _do_get
    return self._create_connection()
  File "/home/airflow/.local/lib/python3.6/site-packages/sqlalchemy/pool/base.py", line 309, in _create_connection
    return _ConnectionRecord(self)
  File "/home/airflow/.local/lib/python3.6/site-packages/sqlalchemy/pool/base.py", line 440, in __init__
    self.__connect(first_connect_check=True)
  File "/home/airflow/.local/lib/python3.6/site-packages/sqlalchemy/pool/base.py", line 661, in __connect
    pool.logger.debug("Error on connect(): %s", e)
  File "/home/airflow/.local/lib/python3.6/site-packages/sqlalchemy/util/langhelpers.py", line 70, in __exit__
    with_traceback=exc_tb,
  File "/home/airflow/.local/lib/python3.6/site-packages/sqlalchemy/util/compat.py", line 182, in raise_
    raise exception
  File "/home/airflow/.local/lib/python3.6/site-packages/sqlalchemy/pool/base.py", line 656, in __connect
    connection = pool._invoke_creator(self)
  File "/home/airflow/.local/lib/python3.6/site-packages/sqlalchemy/engine/strategies.py", line 114, in connect
    return dialect.connect(*cargs, **cparams)
  File "/home/airflow/.local/lib/python3.6/site-packages/sqlalchemy/engine/default.py", line 508, in connect
    return self.dbapi.connect(*cargs, **cparams)
  File "/home/airflow/.local/lib/python3.6/site-packages/psycopg2/__init__.py", line 127, in connect
    conn = _connect(dsn, connection_factory=connection_factory, **kwasync)
psycopg2.OperationalError: could not connect to server: Connection refused
	Is the server running on host "127.0.0.1" and accepting
	TCP/IP connections on port 5432?


The above exception was the direct cause of the following exception:

Traceback (most recent call last):
  File "/home/airflow/.local/lib/python3.6/site-packages/airflow/models/taskinstance.py", line 1112, in _run_raw_task
    self._prepare_and_execute_task_with_callbacks(context, task)
  File "/home/airflow/.local/lib/python3.6/site-packages/airflow/models/taskinstance.py", line 1285, in _prepare_and_execute_task_with_callbacks
    result = self._execute_task(context, task_copy)
  File "/home/airflow/.local/lib/python3.6/site-packages/airflow/models/taskinstance.py", line 1315, in _execute_task
    result = task_copy.execute(context=context)
  File "/home/airflow/.local/lib/python3.6/site-packages/airflow/operators/python.py", line 117, in execute
    return_value = self.execute_callable()
  File "/home/airflow/.local/lib/python3.6/site-packages/airflow/operators/python.py", line 128, in execute_callable
    return self.python_callable(*self.op_args, **self.op_kwargs)
  File "/opt/airflow/dags/company_forecasting.py", line 103, in read_and_convertColumns
    data_company.to_sql('companyA01', engine, method=psql_insert_copy)
  File "/home/airflow/.local/lib/python3.6/site-packages/pandas/core/generic.py", line 2615, in to_sql
    method=method,
  File "/home/airflow/.local/lib/python3.6/site-packages/pandas/io/sql.py", line 598, in to_sql
    method=method,
  File "/home/airflow/.local/lib/python3.6/site-packages/pandas/io/sql.py", line 1393, in to_sql
    table.create()
  File "/home/airflow/.local/lib/python3.6/site-packages/pandas/io/sql.py", line 721, in create
    if self.exists():
  File "/home/airflow/.local/lib/python3.6/site-packages/pandas/io/sql.py", line 708, in exists
    return self.pd_sql.has_table(self.name, self.schema)
  File "/home/airflow/.local/lib/python3.6/site-packages/pandas/io/sql.py", line 1431, in has_table
    self.connectable.dialect.has_table, name, schema or self.meta.schema
  File "/home/airflow/.local/lib/python3.6/site-packages/sqlalchemy/engine/base.py", line 2211, in run_callable
    with self._contextual_connect() as conn:
  File "/home/airflow/.local/lib/python3.6/site-packages/sqlalchemy/engine/base.py", line 2302, in _contextual_connect
    self._wrap_pool_connect(self.pool.connect, None),
  File "/home/airflow/.local/lib/python3.6/site-packages/sqlalchemy/engine/base.py", line 2340, in _wrap_pool_connect
    e, dialect, self
  File "/home/airflow/.local/lib/python3.6/site-packages/sqlalchemy/engine/base.py", line 1584, in _handle_dbapi_exception_noconnection
    sqlalchemy_exception, with_traceback=exc_info[2], from_=e
  File "/home/airflow/.local/lib/python3.6/site-packages/sqlalchemy/util/compat.py", line 182, in raise_
    raise exception
  File "/home/airflow/.local/lib/python3.6/site-packages/sqlalchemy/engine/base.py", line 2336, in _wrap_pool_connect
    return fn()
  File "/home/airflow/.local/lib/python3.6/site-packages/sqlalchemy/pool/base.py", line 364, in connect
    return _ConnectionFairy._checkout(self)
  File "/home/airflow/.local/lib/python3.6/site-packages/sqlalchemy/pool/base.py", line 778, in _checkout
    fairy = _ConnectionRecord.checkout(pool)
  File "/home/airflow/.local/lib/python3.6/site-packages/sqlalchemy/pool/base.py", line 495, in checkout
    rec = pool._do_get()
  File "/home/airflow/.local/lib/python3.6/site-packages/sqlalchemy/pool/impl.py", line 140, in _do_get
    self._dec_overflow()
  File "/home/airflow/.local/lib/python3.6/site-packages/sqlalchemy/util/langhelpers.py", line 70, in __exit__
    with_traceback=exc_tb,
  File "/home/airflow/.local/lib/python3.6/site-packages/sqlalchemy/util/compat.py", line 182, in raise_
    raise exception
  File "/home/airflow/.local/lib/python3.6/site-packages/sqlalchemy/pool/impl.py", line 137, in _do_get
    return self._create_connection()
  File "/home/airflow/.local/lib/python3.6/site-packages/sqlalchemy/pool/base.py", line 309, in _create_connection
    return _ConnectionRecord(self)
  File "/home/airflow/.local/lib/python3.6/site-packages/sqlalchemy/pool/base.py", line 440, in __init__
    self.__connect(first_connect_check=True)
  File "/home/airflow/.local/lib/python3.6/site-packages/sqlalchemy/pool/base.py", line 661, in __connect
    pool.logger.debug("Error on connect(): %s", e)
  File "/home/airflow/.local/lib/python3.6/site-packages/sqlalchemy/util/langhelpers.py", line 70, in __exit__
    with_traceback=exc_tb,
  File "/home/airflow/.local/lib/python3.6/site-packages/sqlalchemy/util/compat.py", line 182, in raise_
    raise exception
  File "/home/airflow/.local/lib/python3.6/site-packages/sqlalchemy/pool/base.py", line 656, in __connect
    connection = pool._invoke_creator(self)
  File "/home/airflow/.local/lib/python3.6/site-packages/sqlalchemy/engine/strategies.py", line 114, in connect
    return dialect.connect(*cargs, **cparams)
  File "/home/airflow/.local/lib/python3.6/site-packages/sqlalchemy/engine/default.py", line 508, in connect
    return self.dbapi.connect(*cargs, **cparams)
  File "/home/airflow/.local/lib/python3.6/site-packages/psycopg2/__init__.py", line 127, in connect
    conn = _connect(dsn, connection_factory=connection_factory, **kwasync)
sqlalchemy.exc.OperationalError: (psycopg2.OperationalError) could not connect to server: Connection refused
	Is the server running on host "127.0.0.1" and accepting
	TCP/IP connections on port 5432?

(Background on this error at: http://sqlalche.me/e/13/e3q8)
[2022-06-25 19:31:49,735] {taskinstance.py:1503} INFO - Marking task as FAILED. dag_id=SDG_Enrique_V0, task_id=readCSV_convertColumns, execution_date=20220625T193114, start_date=20220625T193131, end_date=20220625T193149
[2022-06-25 19:31:49,809] {local_task_job.py:146} INFO - Task exited with return code 1
