[2022-06-25 19:49:56,069] {taskinstance.py:851} INFO - Dependencies all met for <TaskInstance: SDG_Enrique_V0.readCSV_convertColumns 2022-06-25T19:49:52.983658+00:00 [queued]>
[2022-06-25 19:49:56,194] {taskinstance.py:851} INFO - Dependencies all met for <TaskInstance: SDG_Enrique_V0.readCSV_convertColumns 2022-06-25T19:49:52.983658+00:00 [queued]>
[2022-06-25 19:49:56,199] {taskinstance.py:1042} INFO - 
--------------------------------------------------------------------------------
[2022-06-25 19:49:56,200] {taskinstance.py:1043} INFO - Starting attempt 1 of 1
[2022-06-25 19:49:56,201] {taskinstance.py:1044} INFO - 
--------------------------------------------------------------------------------
[2022-06-25 19:49:56,226] {taskinstance.py:1063} INFO - Executing <Task(PythonOperator): readCSV_convertColumns> on 2022-06-25T19:49:52.983658+00:00
[2022-06-25 19:49:56,254] {standard_task_runner.py:52} INFO - Started process 1408 to run task
[2022-06-25 19:49:56,279] {standard_task_runner.py:76} INFO - Running: ['airflow', 'tasks', 'run', 'SDG_Enrique_V0', 'readCSV_convertColumns', '2022-06-25T19:49:52.983658+00:00', '--job-id', '122', '--pool', 'default_pool', '--raw', '--subdir', 'DAGS_FOLDER/company_forecasting.py', '--cfg-path', '/tmp/tmpoasclmmo', '--error-file', '/tmp/tmpsje4c8hj']
[2022-06-25 19:49:56,288] {standard_task_runner.py:77} INFO - Job 122: Subtask readCSV_convertColumns
[2022-06-25 19:49:56,481] {logging_mixin.py:104} INFO - Running <TaskInstance: SDG_Enrique_V0.readCSV_convertColumns 2022-06-25T19:49:52.983658+00:00 [running]> on host 5e8dc4b25004
[2022-06-25 19:49:56,586] {taskinstance.py:1257} INFO - Exporting the following env vars:
AIRFLOW_CTX_DAG_EMAIL=enrique-liebana@outlook.com
AIRFLOW_CTX_DAG_OWNER=Enrique
AIRFLOW_CTX_DAG_ID=SDG_Enrique_V0
AIRFLOW_CTX_TASK_ID=readCSV_convertColumns
AIRFLOW_CTX_EXECUTION_DATE=2022-06-25T19:49:52.983658+00:00
AIRFLOW_CTX_DAG_RUN_ID=manual__2022-06-25T19:49:52.983658+00:00
[2022-06-25 19:49:57,005] {logging_mixin.py:104} WARNING - /home/airflow/.local/lib/python3.6/site-packages/airflow/models/taskinstance.py:1315 DtypeWarning: Columns (14,46,56,59) have mixed types.Specify dtype option on import or set low_memory=False.
[2022-06-25 19:49:57,174] {logging_mixin.py:104} INFO -   rev_mean mou_mean totmrc_mean  ... creditcd eqpdays customer_id
0  23,9975   219,25        22,5  ...        Y   361.0   1000001.0
1  57,4925   482,75      37,425  ...        Y   240.0   1000002.0
2    16,99    10,25       16,99  ...        Y  1504.0   1000003.0
3       38      7,5          38  ...        Y  1812.0   1000004.0
4    55,23    570,5       71,98  ...        Y   434.0   1000005.0

[5 rows x 100 columns]
[2022-06-25 19:49:57,176] {logging_mixin.py:104} INFO - rev_mean        object
mou_mean        object
totmrc_mean     object
da_mean         object
ovrmou_mean     object
                ...   
kid11_15        object
kid16_17        object
creditcd        object
eqpdays        float64
customer_id    float64
Length: 100, dtype: object
[2022-06-25 19:49:57,177] {logging_mixin.py:104} INFO - **************** FLOAT COLUmNS *********************
[2022-06-25 19:49:57,619] {logging_mixin.py:104} INFO - **************** OBJECT COLUmNS *********************
[2022-06-25 19:49:57,676] {logging_mixin.py:104} INFO - ************+***********RESULTS*****************************
[2022-06-25 19:49:57,679] {logging_mixin.py:104} INFO - FLOAT64 (8628, 67)
[2022-06-25 19:49:57,681] {logging_mixin.py:104} INFO - INT64 (8628, 12)
[2022-06-25 19:49:57,685] {logging_mixin.py:104} INFO - STRING (8628, 21)
[2022-06-25 19:49:58,832] {base.py:74} INFO - Using connection to: id: postgres_conection. Host: host.docker.internal, Port: 5432, Schema: data_company, Login: airflow, Password: XXXXXXXX, extra: None
[2022-06-25 19:49:58,847] {taskinstance.py:1455} ERROR - relation "company_a01" does not exist
Traceback (most recent call last):
  File "/home/airflow/.local/lib/python3.6/site-packages/airflow/models/taskinstance.py", line 1112, in _run_raw_task
    self._prepare_and_execute_task_with_callbacks(context, task)
  File "/home/airflow/.local/lib/python3.6/site-packages/airflow/models/taskinstance.py", line 1285, in _prepare_and_execute_task_with_callbacks
    result = self._execute_task(context, task_copy)
  File "/home/airflow/.local/lib/python3.6/site-packages/airflow/models/taskinstance.py", line 1315, in _execute_task
    result = task_copy.execute(context=context)
  File "/home/airflow/.local/lib/python3.6/site-packages/airflow/operators/python.py", line 117, in execute
    return_value = self.execute_callable()
  File "/home/airflow/.local/lib/python3.6/site-packages/airflow/operators/python.py", line 128, in execute_callable
    return self.python_callable(*self.op_args, **self.op_kwargs)
  File "/opt/airflow/dags/company_forecasting.py", line 106, in read_and_convertColumns
    cursor.execute("COPY company_A01 FROM '/processed_data/company_A01.csv' DELIMITER ',' CSV HEADER;")
psycopg2.errors.UndefinedTable: relation "company_a01" does not exist

[2022-06-25 19:49:58,855] {taskinstance.py:1503} INFO - Marking task as FAILED. dag_id=SDG_Enrique_V0, task_id=readCSV_convertColumns, execution_date=20220625T194952, start_date=20220625T194956, end_date=20220625T194958
[2022-06-25 19:49:58,927] {local_task_job.py:146} INFO - Task exited with return code 1
