[2022-06-25 17:50:51,424] {taskinstance.py:851} INFO - Dependencies all met for <TaskInstance: SDG_Enrique_V0.readCSV_convertColumns 2022-06-25T17:50:37.926651+00:00 [queued]>
[2022-06-25 17:50:51,442] {taskinstance.py:851} INFO - Dependencies all met for <TaskInstance: SDG_Enrique_V0.readCSV_convertColumns 2022-06-25T17:50:37.926651+00:00 [queued]>
[2022-06-25 17:50:51,443] {taskinstance.py:1042} INFO - 
--------------------------------------------------------------------------------
[2022-06-25 17:50:51,443] {taskinstance.py:1043} INFO - Starting attempt 1 of 1
[2022-06-25 17:50:51,444] {taskinstance.py:1044} INFO - 
--------------------------------------------------------------------------------
[2022-06-25 17:50:51,452] {taskinstance.py:1063} INFO - Executing <Task(PythonOperator): readCSV_convertColumns> on 2022-06-25T17:50:37.926651+00:00
[2022-06-25 17:50:51,457] {standard_task_runner.py:52} INFO - Started process 200 to run task
[2022-06-25 17:50:51,461] {standard_task_runner.py:76} INFO - Running: ['airflow', 'tasks', 'run', 'SDG_Enrique_V0', 'readCSV_convertColumns', '2022-06-25T17:50:37.926651+00:00', '--job-id', '92', '--pool', 'default_pool', '--raw', '--subdir', 'DAGS_FOLDER/company_forecasting.py', '--cfg-path', '/tmp/tmpd265mxw5', '--error-file', '/tmp/tmpjj576t24']
[2022-06-25 17:50:51,463] {standard_task_runner.py:77} INFO - Job 92: Subtask readCSV_convertColumns
[2022-06-25 17:50:51,505] {logging_mixin.py:104} INFO - Running <TaskInstance: SDG_Enrique_V0.readCSV_convertColumns 2022-06-25T17:50:37.926651+00:00 [running]> on host 9ed5e21ae5e4
[2022-06-25 17:50:51,544] {taskinstance.py:1257} INFO - Exporting the following env vars:
AIRFLOW_CTX_DAG_EMAIL=enrique-liebana@outlook.com
AIRFLOW_CTX_DAG_OWNER=Enrique
AIRFLOW_CTX_DAG_ID=SDG_Enrique_V0
AIRFLOW_CTX_TASK_ID=readCSV_convertColumns
AIRFLOW_CTX_EXECUTION_DATE=2022-06-25T17:50:37.926651+00:00
AIRFLOW_CTX_DAG_RUN_ID=manual__2022-06-25T17:50:37.926651+00:00
[2022-06-25 17:50:52,555] {logging_mixin.py:104} INFO - **************** FLOAT COLUMNS *********************
[2022-06-25 17:50:52,559] {taskinstance.py:1455} ERROR - 'rev_Mean'
Traceback (most recent call last):
  File "/home/airflow/.local/lib/python3.6/site-packages/pandas/core/indexes/base.py", line 2898, in get_loc
    return self._engine.get_loc(casted_key)
  File "pandas/_libs/index.pyx", line 70, in pandas._libs.index.IndexEngine.get_loc
  File "pandas/_libs/index.pyx", line 101, in pandas._libs.index.IndexEngine.get_loc
  File "pandas/_libs/hashtable_class_helper.pxi", line 1675, in pandas._libs.hashtable.PyObjectHashTable.get_item
  File "pandas/_libs/hashtable_class_helper.pxi", line 1683, in pandas._libs.hashtable.PyObjectHashTable.get_item
KeyError: 'rev_Mean'

The above exception was the direct cause of the following exception:

Traceback (most recent call last):
  File "/home/airflow/.local/lib/python3.6/site-packages/airflow/models/taskinstance.py", line 1112, in _run_raw_task
    self._prepare_and_execute_task_with_callbacks(context, task)
  File "/home/airflow/.local/lib/python3.6/site-packages/airflow/models/taskinstance.py", line 1285, in _prepare_and_execute_task_with_callbacks
    result = self._execute_task(context, task_copy)
  File "/home/airflow/.local/lib/python3.6/site-packages/airflow/models/taskinstance.py", line 1315, in _execute_task
    result = task_copy.execute(context=context)
  File "/home/airflow/.local/lib/python3.6/site-packages/airflow/operators/python.py", line 117, in execute
    return_value = self.execute_callable()
  File "/home/airflow/.local/lib/python3.6/site-packages/airflow/operators/python.py", line 128, in execute_callable
    return self.python_callable(*self.op_args, **self.op_kwargs)
  File "/opt/airflow/dags/company_forecasting.py", line 65, in read_and_convertColumns
    data_company[a]=data_company[a].str.replace(',','.').astype(float)
  File "/home/airflow/.local/lib/python3.6/site-packages/pandas/core/frame.py", line 2906, in __getitem__
    indexer = self.columns.get_loc(key)
  File "/home/airflow/.local/lib/python3.6/site-packages/pandas/core/indexes/base.py", line 2900, in get_loc
    raise KeyError(key) from err
KeyError: 'rev_Mean'
[2022-06-25 17:50:52,564] {taskinstance.py:1503} INFO - Marking task as FAILED. dag_id=SDG_Enrique_V0, task_id=readCSV_convertColumns, execution_date=20220625T175037, start_date=20220625T175051, end_date=20220625T175052
[2022-06-25 17:50:52,609] {local_task_job.py:146} INFO - Task exited with return code 1
