[2022-06-27 10:12:35,144] {taskinstance.py:851} INFO - Dependencies all met for <TaskInstance: trigger_dag.gridSearchLR 2022-06-27T10:12:33.372290+00:00 [queued]>
[2022-06-27 10:12:35,152] {taskinstance.py:851} INFO - Dependencies all met for <TaskInstance: trigger_dag.gridSearchLR 2022-06-27T10:12:33.372290+00:00 [queued]>
[2022-06-27 10:12:35,153] {taskinstance.py:1042} INFO - 
--------------------------------------------------------------------------------
[2022-06-27 10:12:35,154] {taskinstance.py:1043} INFO - Starting attempt 1 of 1
[2022-06-27 10:12:35,154] {taskinstance.py:1044} INFO - 
--------------------------------------------------------------------------------
[2022-06-27 10:12:35,165] {taskinstance.py:1063} INFO - Executing <Task(PythonOperator): gridSearchLR> on 2022-06-27T10:12:33.372290+00:00
[2022-06-27 10:12:35,170] {standard_task_runner.py:52} INFO - Started process 227 to run task
[2022-06-27 10:12:35,174] {standard_task_runner.py:76} INFO - Running: ['airflow', 'tasks', 'run', 'trigger_dag', 'gridSearchLR', '2022-06-27T10:12:33.372290+00:00', '--job-id', '578', '--pool', 'default_pool', '--raw', '--subdir', 'DAGS_FOLDER/trigger_dag.py', '--cfg-path', '/tmp/tmp6aufqkwr', '--error-file', '/tmp/tmp7kf3m9ts']
[2022-06-27 10:12:35,176] {standard_task_runner.py:77} INFO - Job 578: Subtask gridSearchLR
[2022-06-27 10:12:35,216] {logging_mixin.py:104} INFO - Running <TaskInstance: trigger_dag.gridSearchLR 2022-06-27T10:12:33.372290+00:00 [running]> on host 61d9f46d7859
[2022-06-27 10:12:35,264] {taskinstance.py:1257} INFO - Exporting the following env vars:
AIRFLOW_CTX_DAG_OWNER=airflow
AIRFLOW_CTX_DAG_ID=trigger_dag
AIRFLOW_CTX_TASK_ID=gridSearchLR
AIRFLOW_CTX_EXECUTION_DATE=2022-06-27T10:12:33.372290+00:00
AIRFLOW_CTX_DAG_RUN_ID=manual__2022-06-27T10:12:33.372290+00:00
[2022-06-27 10:12:35,330] {logging_mixin.py:104} WARNING - 2022/06/27 10:12:35 WARNING mlflow.tracking.context.git_context: Failed to import Git (the Git executable is probably not on your PATH), so Git SHA is not available. Error: Failed to initialize: Bad git executable.
The git executable must be specified in one of the following ways:
    - be included in your $PATH
    - be set via $GIT_PYTHON_GIT_EXECUTABLE
    - explicitly set via git.refresh()

All git commands will error until this is rectified.

This initial warning can be silenced or aggravated in the future by setting the
$GIT_PYTHON_REFRESH environment variable. Use one of the following values:
    - quiet|q|silence|s|none|n|0: for no warning or exception
    - warn|w|warning|1: for a printed warning
    - error|e|raise|r|2: for a raised exception

Example:
    export GIT_PYTHON_REFRESH=quiet
[2022-06-27 10:12:35,330] {logging_mixin.py:104} WARNING - 
[2022-06-27 10:12:35,340] {logging_mixin.py:104} INFO - Running mlflow_tracking.py
[2022-06-27 10:12:35,342] {taskinstance.py:1455} ERROR - Run 'd618510f03274e2aaa19cf01fdb87701' not found
Traceback (most recent call last):
  File "/opt/airflow/dags/trigger_dag.py", line 28, in prueba
    mlflow.log_param("param1", randint(0, 100))
  File "/home/airflow/.local/lib/python3.6/site-packages/mlflow/tracking/fluent.py", line 418, in log_param
    MlflowClient().log_param(run_id, key, value)
  File "/home/airflow/.local/lib/python3.6/site-packages/mlflow/tracking/client.py", line 743, in log_param
    self._tracking_client.log_param(run_id, key, value)
  File "/home/airflow/.local/lib/python3.6/site-packages/mlflow/tracking/_tracking_service/client.py", line 248, in log_param
    raise e
  File "/home/airflow/.local/lib/python3.6/site-packages/mlflow/tracking/_tracking_service/client.py", line 242, in log_param
    self.store.log_param(run_id, param)
  File "/home/airflow/.local/lib/python3.6/site-packages/mlflow/store/tracking/file_store.py", line 796, in log_param
    run_info = self._get_run_info(run_id)
  File "/home/airflow/.local/lib/python3.6/site-packages/mlflow/store/tracking/file_store.py", line 552, in _get_run_info
    "Run '%s' not found" % run_uuid, databricks_pb2.RESOURCE_DOES_NOT_EXIST
mlflow.exceptions.MlflowException: Run 'd618510f03274e2aaa19cf01fdb87701' not found

During handling of the above exception, another exception occurred:

Traceback (most recent call last):
  File "/home/airflow/.local/lib/python3.6/site-packages/airflow/models/taskinstance.py", line 1112, in _run_raw_task
    self._prepare_and_execute_task_with_callbacks(context, task)
  File "/home/airflow/.local/lib/python3.6/site-packages/airflow/models/taskinstance.py", line 1285, in _prepare_and_execute_task_with_callbacks
    result = self._execute_task(context, task_copy)
  File "/home/airflow/.local/lib/python3.6/site-packages/airflow/models/taskinstance.py", line 1315, in _execute_task
    result = task_copy.execute(context=context)
  File "/home/airflow/.local/lib/python3.6/site-packages/airflow/operators/python.py", line 117, in execute
    return_value = self.execute_callable()
  File "/home/airflow/.local/lib/python3.6/site-packages/airflow/operators/python.py", line 128, in execute_callable
    return self.python_callable(*self.op_args, **self.op_kwargs)
  File "/opt/airflow/dags/trigger_dag.py", line 39, in prueba
    mlflow.log_artifacts("outputs")
  File "/home/airflow/.local/lib/python3.6/site-packages/mlflow/tracking/fluent.py", line 150, in __exit__
    end_run(RunStatus.to_string(status))
  File "/home/airflow/.local/lib/python3.6/site-packages/mlflow/tracking/fluent.py", line 331, in end_run
    MlflowClient().set_terminated(run.info.run_id, status)
  File "/home/airflow/.local/lib/python3.6/site-packages/mlflow/tracking/client.py", line 1458, in set_terminated
    self._tracking_client.set_terminated(run_id, status, end_time)
  File "/home/airflow/.local/lib/python3.6/site-packages/mlflow/tracking/_tracking_service/client.py", line 402, in set_terminated
    run_id, run_status=RunStatus.from_string(status), end_time=end_time
  File "/home/airflow/.local/lib/python3.6/site-packages/mlflow/store/tracking/file_store.py", line 479, in update_run_info
    run_info = self._get_run_info(run_id)
  File "/home/airflow/.local/lib/python3.6/site-packages/mlflow/store/tracking/file_store.py", line 552, in _get_run_info
    "Run '%s' not found" % run_uuid, databricks_pb2.RESOURCE_DOES_NOT_EXIST
mlflow.exceptions.MlflowException: Run 'd618510f03274e2aaa19cf01fdb87701' not found
[2022-06-27 10:12:35,347] {taskinstance.py:1503} INFO - Marking task as FAILED. dag_id=trigger_dag, task_id=gridSearchLR, execution_date=20220627T101233, start_date=20220627T101235, end_date=20220627T101235
[2022-06-27 10:12:35,389] {local_task_job.py:146} INFO - Task exited with return code 1
